MotChallenge2DBox
dancetrack0026
Traceback (most recent call last):
  File "/root/autodl-tmp/trackwithdepth/DanceTrack/TrackEval/trackeval/eval.py", line 86, in evaluate
    res[curr_seq] = eval_sequence(curr_seq, dataset, tracker, class_list, metrics_list,
                    ^^^^^^^^^^^^^^^^^^^^^^^^^^^^^^^^^^^^^^^^^^^^^^^^^^^^^^^^^^^^^^^^^^^
  File "/root/autodl-tmp/trackwithdepth/DanceTrack/TrackEval/trackeval/_timing.py", line 17, in wrap
    result = f(*args, **kw)
             ^^^^^^^^^^^^^^
  File "/root/autodl-tmp/trackwithdepth/DanceTrack/TrackEval/trackeval/eval.py", line 191, in eval_sequence
    raw_data = dataset.get_raw_seq_data(tracker, seq)
               ^^^^^^^^^^^^^^^^^^^^^^^^^^^^^^^^^^^^^^
  File "/root/autodl-tmp/trackwithdepth/DanceTrack/TrackEval/trackeval/_timing.py", line 17, in wrap
    result = f(*args, **kw)
             ^^^^^^^^^^^^^^
  File "/root/autodl-tmp/trackwithdepth/DanceTrack/TrackEval/trackeval/datasets/_base_dataset.py", line 92, in get_raw_seq_data
    raw_gt_data = self._load_raw_file(tracker, seq, is_gt=True)
                  ^^^^^^^^^^^^^^^^^^^^^^^^^^^^^^^^^^^^^^^^^^^^^
  File "/root/autodl-tmp/trackwithdepth/DanceTrack/TrackEval/trackeval/datasets/mot_challenge_2d_box.py", line 227, in _load_raw_file
    time_data = np.asarray(read_data[time_key], dtype=np.float)
                                                      ^^^^^^^^
  File "/root/miniconda3/envs/dfine/lib/python3.11/site-packages/numpy/__init__.py", line 397, in __getattr__
    raise AttributeError(__former_attrs__[attr], name=None)
AttributeError: module 'numpy' has no attribute 'float'.
`np.float` was a deprecated alias for the builtin `float`. To avoid this error in existing code, use `float` by itself. Doing this will not modify any behavior and is safe. If you specifically wanted the numpy scalar type, use `np.float64` here.
The aliases was originally deprecated in NumPy 1.20; for more details and guidance see the original release note at:
    https://numpy.org/devdocs/release/1.20.0-notes.html#deprecations





MotChallenge2DBox
dancetrack0026
Traceback (most recent call last):
  File "/root/autodl-tmp/trackwithdepth/DanceTrack/TrackEval/trackeval/datasets/_base_dataset.py", line 152, in _load_simple_text_file
    fp = open(file)
         ^^^^^^^^^^
FileNotFoundError: [Errno 2] No such file or directory: './YOLOX_outputs/DepthMOT/track_vis/dancetrack0026/data/dancetrack0005.txt'

During handling of the above exception, another exception occurred:

Traceback (most recent call last):
  File "/root/autodl-tmp/trackwithdepth/DanceTrack/TrackEval/trackeval/eval.py", line 86, in evaluate
    res[curr_seq] = eval_sequence(curr_seq, dataset, tracker, class_list, metrics_list,
                    ^^^^^^^^^^^^^^^^^^^^^^^^^^^^^^^^^^^^^^^^^^^^^^^^^^^^^^^^^^^^^^^^^^^
  File "/root/autodl-tmp/trackwithdepth/DanceTrack/TrackEval/trackeval/_timing.py", line 17, in wrap
    result = f(*args, **kw)
             ^^^^^^^^^^^^^^
  File "/root/autodl-tmp/trackwithdepth/DanceTrack/TrackEval/trackeval/eval.py", line 191, in eval_sequence
    raw_data = dataset.get_raw_seq_data(tracker, seq)
               ^^^^^^^^^^^^^^^^^^^^^^^^^^^^^^^^^^^^^^
  File "/root/autodl-tmp/trackwithdepth/DanceTrack/TrackEval/trackeval/_timing.py", line 17, in wrap
    result = f(*args, **kw)
             ^^^^^^^^^^^^^^
  File "/root/autodl-tmp/trackwithdepth/DanceTrack/TrackEval/trackeval/datasets/_base_dataset.py", line 93, in get_raw_seq_data
    raw_tracker_data = self._load_raw_file(tracker, seq, is_gt=False)
                       ^^^^^^^^^^^^^^^^^^^^^^^^^^^^^^^^^^^^^^^^^^^^^^
  File "/root/autodl-tmp/trackwithdepth/DanceTrack/TrackEval/trackeval/datasets/mot_challenge_2d_box.py", line 200, in _load_raw_file
    read_data, ignore_data = self._load_simple_text_file(file, is_zipped=self.data_is_zipped, zip_file=zip_file)
                             ^^^^^^^^^^^^^^^^^^^^^^^^^^^^^^^^^^^^^^^^^^^^^^^^^^^^^^^^^^^^^^^^^^^^^^^^^^^^^^^^^^^
  File "/root/autodl-tmp/trackwithdepth/DanceTrack/TrackEval/trackeval/datasets/_base_dataset.py", line 209, in _load_simple_text_file
    raise TrackEvalException(
DanceTrack.TrackEval.trackeval.utils.TrackEvalException: File dancetrack0005.txt cannot be read because it is either not present or invalidly formatted





MotChallenge2DBox
dancetrack0026
Traceback (most recent call last):
  File "/root/autodl-tmp/trackwithdepth/DanceTrack/TrackEval/trackeval/eval.py", line 86, in evaluate
    res[curr_seq] = eval_sequence(curr_seq, dataset, tracker, class_list, metrics_list,
                    ^^^^^^^^^^^^^^^^^^^^^^^^^^^^^^^^^^^^^^^^^^^^^^^^^^^^^^^^^^^^^^^^^^^
  File "/root/autodl-tmp/trackwithdepth/DanceTrack/TrackEval/trackeval/_timing.py", line 17, in wrap
    result = f(*args, **kw)
             ^^^^^^^^^^^^^^
  File "/root/autodl-tmp/trackwithdepth/DanceTrack/TrackEval/trackeval/eval.py", line 195, in eval_sequence
    data = dataset.get_preprocessed_seq_data(raw_data, cls)
           ^^^^^^^^^^^^^^^^^^^^^^^^^^^^^^^^^^^^^^^^^^^^^^^^
  File "/root/autodl-tmp/trackwithdepth/DanceTrack/TrackEval/trackeval/_timing.py", line 17, in wrap
    result = f(*args, **kw)
             ^^^^^^^^^^^^^^
  File "/root/autodl-tmp/trackwithdepth/DanceTrack/TrackEval/trackeval/datasets/mot_challenge_2d_box.py", line 358, in get_preprocessed_seq_data
    to_remove_tracker = np.array([], np.int)
                                     ^^^^^^
  File "/root/miniconda3/envs/dfine/lib/python3.11/site-packages/numpy/__init__.py", line 397, in __getattr__
    raise AttributeError(__former_attrs__[attr], name=None)
AttributeError: module 'numpy' has no attribute 'int'.
`np.int` was a deprecated alias for the builtin `int`. To avoid this error in existing code, use `int` by itself. Doing this will not modify any behavior and is safe. When replacing `np.int`, you may wish to use e.g. `np.int64` or `np.int32` to specify the precision. If you wish to review your current use, check the release note link for additional information.
The aliases was originally deprecated in NumPy 1.20; for more details and guidance see the original release note at:
    https://numpy.org/devdocs/release/1.20.0-notes.html#deprecations





MotChallenge2DBox
dancetrack0026
Traceback (most recent call last):
  File "/root/autodl-tmp/trackwithdepth/DanceTrack/TrackEval/trackeval/eval.py", line 86, in evaluate
    res[curr_seq] = eval_sequence(curr_seq, dataset, tracker, class_list, metrics_list,
                    ^^^^^^^^^^^^^^^^^^^^^^^^^^^^^^^^^^^^^^^^^^^^^^^^^^^^^^^^^^^^^^^^^^^
  File "/root/autodl-tmp/trackwithdepth/DanceTrack/TrackEval/trackeval/_timing.py", line 17, in wrap
    result = f(*args, **kw)
             ^^^^^^^^^^^^^^
  File "/root/autodl-tmp/trackwithdepth/DanceTrack/TrackEval/trackeval/eval.py", line 195, in eval_sequence
    data = dataset.get_preprocessed_seq_data(raw_data, cls)
           ^^^^^^^^^^^^^^^^^^^^^^^^^^^^^^^^^^^^^^^^^^^^^^^^
  File "/root/autodl-tmp/trackwithdepth/DanceTrack/TrackEval/trackeval/_timing.py", line 17, in wrap
    result = f(*args, **kw)
             ^^^^^^^^^^^^^^
  File "/root/autodl-tmp/trackwithdepth/DanceTrack/TrackEval/trackeval/datasets/mot_challenge_2d_box.py", line 412, in get_preprocessed_seq_data
    data['gt_ids'][t] = gt_id_map[data['gt_ids'][t]].astype(np.int)
                                                            ^^^^^^
  File "/root/miniconda3/envs/dfine/lib/python3.11/site-packages/numpy/__init__.py", line 397, in __getattr__
    raise AttributeError(__former_attrs__[attr], name=None)
AttributeError: module 'numpy' has no attribute 'int'.
`np.int` was a deprecated alias for the builtin `int`. To avoid this error in existing code, use `int` by itself. Doing this will not modify any behavior and is safe. When replacing `np.int`, you may wish to use e.g. `np.int64` or `np.int32` to specify the precision. If you wish to review your current use, check the release note link for additional information.
The aliases was originally deprecated in NumPy 1.20; for more details and guidance see the original release note at:
    https://numpy.org/devdocs/release/1.20.0-notes.html#deprecations





MotChallenge2DBox
dancetrack0026
Traceback (most recent call last):
  File "/root/autodl-tmp/trackwithdepth/DanceTrack/TrackEval/trackeval/eval.py", line 86, in evaluate
    res[curr_seq] = eval_sequence(curr_seq, dataset, tracker, class_list, metrics_list,
                    ^^^^^^^^^^^^^^^^^^^^^^^^^^^^^^^^^^^^^^^^^^^^^^^^^^^^^^^^^^^^^^^^^^^
  File "/root/autodl-tmp/trackwithdepth/DanceTrack/TrackEval/trackeval/_timing.py", line 17, in wrap
    result = f(*args, **kw)
             ^^^^^^^^^^^^^^
  File "/root/autodl-tmp/trackwithdepth/DanceTrack/TrackEval/trackeval/eval.py", line 197, in eval_sequence
    seq_res[cls][met_name] = metric.eval_sequence(data)
                             ^^^^^^^^^^^^^^^^^^^^^^^^^^
  File "/root/autodl-tmp/trackwithdepth/DanceTrack/TrackEval/trackeval/_timing.py", line 17, in wrap
    result = f(*args, **kw)
             ^^^^^^^^^^^^^^
  File "/root/autodl-tmp/trackwithdepth/DanceTrack/TrackEval/trackeval/metrics/hota.py", line 31, in eval_sequence
    res[field] = np.zeros((len(self.array_labels)), dtype=np.float)
                                                          ^^^^^^^^
  File "/root/miniconda3/envs/dfine/lib/python3.11/site-packages/numpy/__init__.py", line 397, in __getattr__
    raise AttributeError(__former_attrs__[attr], name=None)
AttributeError: module 'numpy' has no attribute 'float'.
`np.float` was a deprecated alias for the builtin `float`. To avoid this error in existing code, use `float` by itself. Doing this will not modify any behavior and is safe. If you specifically wanted the numpy scalar type, use `np.float64` here.
The aliases was originally deprecated in NumPy 1.20; for more details and guidance see the original release note at:
    https://numpy.org/devdocs/release/1.20.0-notes.html#deprecations





MotChallenge2DBox
dancetrack0026
Traceback (most recent call last):
  File "/root/autodl-tmp/trackwithdepth/DanceTrack/TrackEval/trackeval/eval.py", line 86, in evaluate
    res[curr_seq] = eval_sequence(curr_seq, dataset, tracker, class_list, metrics_list,
                    ^^^^^^^^^^^^^^^^^^^^^^^^^^^^^^^^^^^^^^^^^^^^^^^^^^^^^^^^^^^^^^^^^^^
  File "/root/autodl-tmp/trackwithdepth/DanceTrack/TrackEval/trackeval/_timing.py", line 17, in wrap
    result = f(*args, **kw)
             ^^^^^^^^^^^^^^
  File "/root/autodl-tmp/trackwithdepth/DanceTrack/TrackEval/trackeval/eval.py", line 197, in eval_sequence
    seq_res[cls][met_name] = metric.eval_sequence(data)
                             ^^^^^^^^^^^^^^^^^^^^^^^^^^
  File "/root/autodl-tmp/trackwithdepth/DanceTrack/TrackEval/trackeval/_timing.py", line 17, in wrap
    result = f(*args, **kw)
             ^^^^^^^^^^^^^^
  File "/root/autodl-tmp/trackwithdepth/DanceTrack/TrackEval/trackeval/metrics/identity.py", line 83, in eval_sequence
    res['IDFN'] = fn_mat[match_rows, match_cols].sum().astype(np.int)
                                                              ^^^^^^
  File "/root/miniconda3/envs/dfine/lib/python3.11/site-packages/numpy/__init__.py", line 397, in __getattr__
    raise AttributeError(__former_attrs__[attr], name=None)
AttributeError: module 'numpy' has no attribute 'int'.
`np.int` was a deprecated alias for the builtin `int`. To avoid this error in existing code, use `int` by itself. Doing this will not modify any behavior and is safe. When replacing `np.int`, you may wish to use e.g. `np.int64` or `np.int32` to specify the precision. If you wish to review your current use, check the release note link for additional information.
The aliases was originally deprecated in NumPy 1.20; for more details and guidance see the original release note at:
    https://numpy.org/devdocs/release/1.20.0-notes.html#deprecations





MotChallenge2DBox
dancetrack0026
Traceback (most recent call last):
  File "/root/autodl-tmp/trackwithdepth/DanceTrack/TrackEval/trackeval/eval.py", line 86, in evaluate
    res[curr_seq] = eval_sequence(curr_seq, dataset, tracker, class_list, metrics_list,
                    ^^^^^^^^^^^^^^^^^^^^^^^^^^^^^^^^^^^^^^^^^^^^^^^^^^^^^^^^^^^^^^^^^^^
  File "/root/autodl-tmp/trackwithdepth/DanceTrack/TrackEval/trackeval/_timing.py", line 17, in wrap
    result = f(*args, **kw)
             ^^^^^^^^^^^^^^
  File "/root/autodl-tmp/trackwithdepth/DanceTrack/TrackEval/trackeval/eval.py", line 191, in eval_sequence
    raw_data = dataset.get_raw_seq_data(tracker, seq)
               ^^^^^^^^^^^^^^^^^^^^^^^^^^^^^^^^^^^^^^
  File "/root/autodl-tmp/trackwithdepth/DanceTrack/TrackEval/trackeval/_timing.py", line 17, in wrap
    result = f(*args, **kw)
             ^^^^^^^^^^^^^^
  File "/root/autodl-tmp/trackwithdepth/DanceTrack/TrackEval/trackeval/datasets/_base_dataset.py", line 93, in get_raw_seq_data
    raw_tracker_data = self._load_raw_file(tracker, seq, is_gt=False)
                       ^^^^^^^^^^^^^^^^^^^^^^^^^^^^^^^^^^^^^^^^^^^^^^
  File "/root/autodl-tmp/trackwithdepth/DanceTrack/TrackEval/trackeval/datasets/mot_challenge_2d_box.py", line 219, in _load_raw_file
    raise TrackEvalException(
DanceTrack.TrackEval.trackeval.utils.TrackEvalException: Tracking data contains the following invalid timesteps in seq dancetrack0043: 184, , 185, , 186, , 187, , 188, , 189, , 190, , 191, , 192, , 193, , 194, , 195, , 196, , 197, , 198, , 199, , 200, , 201, , 202, , 203, , 204, , 205, , 206, , 207, , 208, , 209, , 210, , 211, , 212, , 213, , 214, , 215, , 216, , 217, , 218, , 219, , 220, , 221, , 222, , 223, , 224, , 225, , 226, , 227, , 228, , 229, , 230, , 231, , 232, , 233, , 234, , 235, , 236, , 237, , 238, , 239, , 240, , 241, , 242, , 243, , 244, , 245, , 246, , 247, , 248, , 249, , 250, , 251, , 252, , 253, , 254, , 255, , 256, , 257, , 258, , 259, , 260, , 261, , 262, , 263, , 264, , 265, , 266, , 267, , 268, , 269, , 270, , 271, 





MotChallenge2DBox
dancetrack0026
Traceback (most recent call last):
  File "/root/autodl-tmp/trackwithdepth/DanceTrack/TrackEval/trackeval/eval.py", line 86, in evaluate
    res[curr_seq] = eval_sequence(curr_seq, dataset, tracker, class_list, metrics_list,
                    ^^^^^^^^^^^^^^^^^^^^^^^^^^^^^^^^^^^^^^^^^^^^^^^^^^^^^^^^^^^^^^^^^^^
  File "/root/autodl-tmp/trackwithdepth/DanceTrack/TrackEval/trackeval/_timing.py", line 17, in wrap
    result = f(*args, **kw)
             ^^^^^^^^^^^^^^
  File "/root/autodl-tmp/trackwithdepth/DanceTrack/TrackEval/trackeval/eval.py", line 191, in eval_sequence
    raw_data = dataset.get_raw_seq_data(tracker, seq)
               ^^^^^^^^^^^^^^^^^^^^^^^^^^^^^^^^^^^^^^
  File "/root/autodl-tmp/trackwithdepth/DanceTrack/TrackEval/trackeval/_timing.py", line 17, in wrap
    result = f(*args, **kw)
             ^^^^^^^^^^^^^^
  File "/root/autodl-tmp/trackwithdepth/DanceTrack/TrackEval/trackeval/datasets/_base_dataset.py", line 93, in get_raw_seq_data
    raw_tracker_data = self._load_raw_file(tracker, seq, is_gt=False)
                       ^^^^^^^^^^^^^^^^^^^^^^^^^^^^^^^^^^^^^^^^^^^^^^
  File "/root/autodl-tmp/trackwithdepth/DanceTrack/TrackEval/trackeval/datasets/mot_challenge_2d_box.py", line 219, in _load_raw_file
    raise TrackEvalException(
DanceTrack.TrackEval.trackeval.utils.TrackEvalException: Tracking data contains the following invalid timesteps in seq dancetrack0043: 184, , 185, , 186, , 187, , 188, , 189, , 190, , 191, , 192, , 193, , 194, , 195, , 196, , 197, , 198, , 199, , 200, , 201, , 202, , 203, , 204, , 205, , 206, , 207, , 208, , 209, , 210, , 211, , 212, , 213, , 214, , 215, , 216, , 217, , 218, , 219, , 220, , 221, , 222, , 223, , 224, , 225, , 226, , 227, , 228, , 229, , 230, , 231, , 232, , 233, , 234, , 235, , 236, , 237, , 238, , 239, , 240, , 241, , 242, , 243, , 244, , 245, , 246, , 247, , 248, , 249, , 250, , 251, , 252, , 253, , 254, , 255, , 256, , 257, , 258, , 259, , 260, , 261, , 262, , 263, , 264, , 265, , 266, , 267, , 268, , 269, , 270, , 271, 





MotChallenge2DBox
dancetrack0026
Traceback (most recent call last):
  File "/root/autodl-tmp/trackwithdepth/DanceTrack/TrackEval/trackeval/eval.py", line 86, in evaluate
    res[curr_seq] = eval_sequence(curr_seq, dataset, tracker, class_list, metrics_list,
                    ^^^^^^^^^^^^^^^^^^^^^^^^^^^^^^^^^^^^^^^^^^^^^^^^^^^^^^^^^^^^^^^^^^^
  File "/root/autodl-tmp/trackwithdepth/DanceTrack/TrackEval/trackeval/_timing.py", line 17, in wrap
    result = f(*args, **kw)
             ^^^^^^^^^^^^^^
  File "/root/autodl-tmp/trackwithdepth/DanceTrack/TrackEval/trackeval/eval.py", line 191, in eval_sequence
    raw_data = dataset.get_raw_seq_data(tracker, seq)
               ^^^^^^^^^^^^^^^^^^^^^^^^^^^^^^^^^^^^^^
  File "/root/autodl-tmp/trackwithdepth/DanceTrack/TrackEval/trackeval/_timing.py", line 17, in wrap
    result = f(*args, **kw)
             ^^^^^^^^^^^^^^
  File "/root/autodl-tmp/trackwithdepth/DanceTrack/TrackEval/trackeval/datasets/_base_dataset.py", line 93, in get_raw_seq_data
    raw_tracker_data = self._load_raw_file(tracker, seq, is_gt=False)
                       ^^^^^^^^^^^^^^^^^^^^^^^^^^^^^^^^^^^^^^^^^^^^^^
  File "/root/autodl-tmp/trackwithdepth/DanceTrack/TrackEval/trackeval/datasets/mot_challenge_2d_box.py", line 219, in _load_raw_file
    raise TrackEvalException(
DanceTrack.TrackEval.trackeval.utils.TrackEvalException: Tracking data contains the following invalid timesteps in seq dancetrack0043: 184, , 185, , 186, , 187, , 188, , 189, , 190, , 191, , 192, , 193, , 194, , 195, , 196, , 197, , 198, , 199, , 200, , 201, , 202, , 203, , 204, , 205, , 206, , 207, , 208, , 209, , 210, , 211, , 212, , 213, , 214, , 215, , 216, , 217, , 218, , 219, , 220, , 221, , 222, , 223, , 224, , 225, , 226, , 227, , 228, , 229, , 230, , 231, , 232, , 233, , 234, , 235, , 236, , 237, , 238, , 239, , 240, , 241, , 242, , 243, , 244, , 245, , 246, , 247, , 248, , 249, , 250, , 251, , 252, , 253, , 254, , 255, , 256, , 257, , 258, , 259, , 260, , 261, , 262, , 263, , 264, , 265, , 266, , 267, , 268, , 269, , 270, , 271, 





MotChallenge2DBox
dancetrack0026
Traceback (most recent call last):
  File "/root/autodl-tmp/trackwithdepth/DanceTrack/TrackEval/trackeval/eval.py", line 86, in evaluate
    res[curr_seq] = eval_sequence(curr_seq, dataset, tracker, class_list, metrics_list,
                    ^^^^^^^^^^^^^^^^^^^^^^^^^^^^^^^^^^^^^^^^^^^^^^^^^^^^^^^^^^^^^^^^^^^
  File "/root/autodl-tmp/trackwithdepth/DanceTrack/TrackEval/trackeval/_timing.py", line 17, in wrap
    result = f(*args, **kw)
             ^^^^^^^^^^^^^^
  File "/root/autodl-tmp/trackwithdepth/DanceTrack/TrackEval/trackeval/eval.py", line 191, in eval_sequence
    raw_data = dataset.get_raw_seq_data(tracker, seq)
               ^^^^^^^^^^^^^^^^^^^^^^^^^^^^^^^^^^^^^^
  File "/root/autodl-tmp/trackwithdepth/DanceTrack/TrackEval/trackeval/_timing.py", line 17, in wrap
    result = f(*args, **kw)
             ^^^^^^^^^^^^^^
  File "/root/autodl-tmp/trackwithdepth/DanceTrack/TrackEval/trackeval/datasets/_base_dataset.py", line 93, in get_raw_seq_data
    raw_tracker_data = self._load_raw_file(tracker, seq, is_gt=False)
                       ^^^^^^^^^^^^^^^^^^^^^^^^^^^^^^^^^^^^^^^^^^^^^^
  File "/root/autodl-tmp/trackwithdepth/DanceTrack/TrackEval/trackeval/datasets/mot_challenge_2d_box.py", line 219, in _load_raw_file
    raise TrackEvalException(
DanceTrack.TrackEval.trackeval.utils.TrackEvalException: Tracking data contains the following invalid timesteps in seq dancetrack0043: 184, , 185, , 186, , 187, , 188, , 189, , 190, , 191, , 192, , 193, , 194, , 195, , 196, , 197, , 198, , 199, , 200, , 201, , 202, , 203, , 204, , 205, , 206, , 207, , 208, , 209, , 210, , 211, , 212, , 213, , 214, , 215, , 216, , 217, , 218, , 219, , 220, , 221, , 222, , 223, , 224, , 225, , 226, , 227, , 228, , 229, , 230, , 231, , 232, , 233, , 234, , 235, , 236, , 237, , 238, , 239, , 240, , 241, , 242, , 243, , 244, , 245, , 246, , 247, , 248, , 249, , 250, , 251, , 252, , 253, , 254, , 255, , 256, , 257, , 258, , 259, , 260, , 261, , 262, , 263, , 264, , 265, , 266, , 267, , 268, , 269, , 270, , 271, 





MotChallenge2DBox
dancetrack0026
Traceback (most recent call last):
  File "/root/autodl-tmp/trackwithdepth/DanceTrack/TrackEval/trackeval/eval.py", line 86, in evaluate
    res[curr_seq] = eval_sequence(curr_seq, dataset, tracker, class_list, metrics_list,
                    ^^^^^^^^^^^^^^^^^^^^^^^^^^^^^^^^^^^^^^^^^^^^^^^^^^^^^^^^^^^^^^^^^^^
  File "/root/autodl-tmp/trackwithdepth/DanceTrack/TrackEval/trackeval/_timing.py", line 17, in wrap
    result = f(*args, **kw)
             ^^^^^^^^^^^^^^
  File "/root/autodl-tmp/trackwithdepth/DanceTrack/TrackEval/trackeval/eval.py", line 191, in eval_sequence
    raw_data = dataset.get_raw_seq_data(tracker, seq)
               ^^^^^^^^^^^^^^^^^^^^^^^^^^^^^^^^^^^^^^
  File "/root/autodl-tmp/trackwithdepth/DanceTrack/TrackEval/trackeval/_timing.py", line 17, in wrap
    result = f(*args, **kw)
             ^^^^^^^^^^^^^^
  File "/root/autodl-tmp/trackwithdepth/DanceTrack/TrackEval/trackeval/datasets/_base_dataset.py", line 92, in get_raw_seq_data
    raw_gt_data = self._load_raw_file(tracker, seq, is_gt=True)
                  ^^^^^^^^^^^^^^^^^^^^^^^^^^^^^^^^^^^^^^^^^^^^^
  File "/root/autodl-tmp/trackwithdepth/DanceTrack/TrackEval/trackeval/datasets/mot_challenge_2d_box.py", line 219, in _load_raw_file
    raise TrackEvalException(
DanceTrack.TrackEval.trackeval.utils.TrackEvalException: Ground-truth data contains the following invalid timesteps in seq dancetrack0043: 180, , 181, , 182, , 183, 





MotChallenge2DBox
dancetrack0026
Traceback (most recent call last):
  File "/root/autodl-tmp/trackwithdepth/DanceTrack/TrackEval/trackeval/eval.py", line 86, in evaluate
    res[curr_seq] = eval_sequence(curr_seq, dataset, tracker, class_list, metrics_list,
                    ^^^^^^^^^^^^^^^^^^^^^^^^^^^^^^^^^^^^^^^^^^^^^^^^^^^^^^^^^^^^^^^^^^^
  File "/root/autodl-tmp/trackwithdepth/DanceTrack/TrackEval/trackeval/_timing.py", line 17, in wrap
    result = f(*args, **kw)
             ^^^^^^^^^^^^^^
  File "/root/autodl-tmp/trackwithdepth/DanceTrack/TrackEval/trackeval/eval.py", line 191, in eval_sequence
    raw_data = dataset.get_raw_seq_data(tracker, seq)
               ^^^^^^^^^^^^^^^^^^^^^^^^^^^^^^^^^^^^^^
  File "/root/autodl-tmp/trackwithdepth/DanceTrack/TrackEval/trackeval/_timing.py", line 17, in wrap
    result = f(*args, **kw)
             ^^^^^^^^^^^^^^
  File "/root/autodl-tmp/trackwithdepth/DanceTrack/TrackEval/trackeval/datasets/_base_dataset.py", line 93, in get_raw_seq_data
    raw_tracker_data = self._load_raw_file(tracker, seq, is_gt=False)
                       ^^^^^^^^^^^^^^^^^^^^^^^^^^^^^^^^^^^^^^^^^^^^^^
  File "/root/autodl-tmp/trackwithdepth/DanceTrack/TrackEval/trackeval/datasets/mot_challenge_2d_box.py", line 219, in _load_raw_file
    raise TrackEvalException(
DanceTrack.TrackEval.trackeval.utils.TrackEvalException: Tracking data contains the following invalid timesteps in seq dancetrack0043: 184, , 185, , 186, , 187, , 188, , 189, , 190, , 191, , 192, , 193, , 194, , 195, , 196, , 197, , 198, , 199, , 200, , 201, , 202, , 203, , 204, , 205, , 206, , 207, , 208, , 209, , 210, , 211, , 212, , 213, , 214, , 215, , 216, , 217, , 218, , 219, , 220, , 221, , 222, , 223, , 224, , 225, , 226, , 227, , 228, , 229, , 230, , 231, , 232, , 233, , 234, , 235, , 236, , 237, , 238, , 239, , 240, , 241, , 242, , 243, , 244, , 245, , 246, , 247, , 248, , 249, , 250, , 251, , 252, , 253, , 254, , 255, , 256, , 257, , 258, , 259, , 260, , 261, , 262, , 263, , 264, , 265, , 266, , 267, , 268, , 269, , 270, , 271, 





MotChallenge2DBox
dancetrack0026
Traceback (most recent call last):
  File "/root/autodl-tmp/trackwithdepth/DanceTrack/TrackEval/trackeval/eval.py", line 86, in evaluate
    res[curr_seq] = eval_sequence(curr_seq, dataset, tracker, class_list, metrics_list,
                    ^^^^^^^^^^^^^^^^^^^^^^^^^^^^^^^^^^^^^^^^^^^^^^^^^^^^^^^^^^^^^^^^^^^
  File "/root/autodl-tmp/trackwithdepth/DanceTrack/TrackEval/trackeval/_timing.py", line 17, in wrap
    result = f(*args, **kw)
             ^^^^^^^^^^^^^^
  File "/root/autodl-tmp/trackwithdepth/DanceTrack/TrackEval/trackeval/eval.py", line 191, in eval_sequence
    raw_data = dataset.get_raw_seq_data(tracker, seq)
               ^^^^^^^^^^^^^^^^^^^^^^^^^^^^^^^^^^^^^^
  File "/root/autodl-tmp/trackwithdepth/DanceTrack/TrackEval/trackeval/_timing.py", line 17, in wrap
    result = f(*args, **kw)
             ^^^^^^^^^^^^^^
  File "/root/autodl-tmp/trackwithdepth/DanceTrack/TrackEval/trackeval/datasets/_base_dataset.py", line 93, in get_raw_seq_data
    raw_tracker_data = self._load_raw_file(tracker, seq, is_gt=False)
                       ^^^^^^^^^^^^^^^^^^^^^^^^^^^^^^^^^^^^^^^^^^^^^^
  File "/root/autodl-tmp/trackwithdepth/DanceTrack/TrackEval/trackeval/datasets/mot_challenge_2d_box.py", line 219, in _load_raw_file
    raise TrackEvalException(
DanceTrack.TrackEval.trackeval.utils.TrackEvalException: Tracking data contains the following invalid timesteps in seq dancetrack0043: 184, , 185, , 186, , 187, , 188, , 189, , 190, , 191, , 192, , 193, , 194, , 195, , 196, , 197, , 198, , 199, , 200, , 201, , 202, , 203, , 204, , 205, , 206, , 207, , 208, , 209, , 210, , 211, , 212, , 213, , 214, , 215, , 216, , 217, , 218, , 219, , 220, , 221, , 222, , 223, , 224, , 225, , 226, , 227, , 228, , 229, , 230, , 231, , 232, , 233, , 234, , 235, , 236, , 237, , 238, , 239, , 240, , 241, , 242, , 243, , 244, , 245, , 246, , 247, , 248, , 249, , 250, , 251, , 252, , 253, , 254, , 255, , 256, , 257, , 258, , 259, , 260, , 261, , 262, , 263, , 264, , 265, , 266, , 267, , 268, , 269, , 270, , 271, 





MotChallenge2DBox
dancetrack0004
Traceback (most recent call last):
  File "/root/autodl-tmp/trackwithdepth/DanceTrack/TrackEval/trackeval/eval.py", line 86, in evaluate
    res[curr_seq] = eval_sequence(curr_seq, dataset, tracker, class_list, metrics_list,
                    ^^^^^^^^^^^^^^^^^^^^^^^^^^^^^^^^^^^^^^^^^^^^^^^^^^^^^^^^^^^^^^^^^^^
  File "/root/autodl-tmp/trackwithdepth/DanceTrack/TrackEval/trackeval/_timing.py", line 17, in wrap
    result = f(*args, **kw)
             ^^^^^^^^^^^^^^
  File "/root/autodl-tmp/trackwithdepth/DanceTrack/TrackEval/trackeval/eval.py", line 191, in eval_sequence
    raw_data = dataset.get_raw_seq_data(tracker, seq)
               ^^^^^^^^^^^^^^^^^^^^^^^^^^^^^^^^^^^^^^
  File "/root/autodl-tmp/trackwithdepth/DanceTrack/TrackEval/trackeval/_timing.py", line 17, in wrap
    result = f(*args, **kw)
             ^^^^^^^^^^^^^^
  File "/root/autodl-tmp/trackwithdepth/DanceTrack/TrackEval/trackeval/datasets/_base_dataset.py", line 93, in get_raw_seq_data
    raw_tracker_data = self._load_raw_file(tracker, seq, is_gt=False)
                       ^^^^^^^^^^^^^^^^^^^^^^^^^^^^^^^^^^^^^^^^^^^^^^
  File "/root/autodl-tmp/trackwithdepth/DanceTrack/TrackEval/trackeval/datasets/mot_challenge_2d_box.py", line 219, in _load_raw_file
    raise TrackEvalException(
DanceTrack.TrackEval.trackeval.utils.TrackEvalException: Tracking data contains the following invalid timesteps in seq dancetrack0018: 504, , 505, , 506, , 507, , 508, , 509, , 510, , 511, , 512, , 513, , 514, , 515, , 516, , 517, , 518, , 519, , 520, , 521, , 522, , 523, , 524, , 525, , 526, , 527, , 528, , 529, , 530, , 531, , 532, , 533, , 534, , 535, , 536, , 537, , 538, , 539, , 540, , 541, , 542, , 543, , 544, , 545, , 546, , 547, , 548, , 549, , 550, , 551, , 552, , 553, , 554, , 555, , 556, , 557, , 558, , 559, , 560, , 561, , 562, , 563, , 564, , 565, , 566, , 567, , 568, , 569, , 570, , 571, , 572, , 573, , 574, , 575, , 576, , 577, , 578, , 579, , 580, , 581, , 582, , 583, , 584, , 585, , 586, , 587, , 588, , 589, , 590, , 591, , 592, , 593, , 594, , 595, , 596, , 597, , 598, , 599, , 600, , 601, , 602, , 603, , 604, , 605, , 606, , 607, , 608, , 609, , 610, , 611, , 612, , 613, , 614, , 615, , 616, , 617, , 618, , 619, , 620, , 621, , 622, , 623, , 624, , 625, , 626, , 627, , 628, , 629, , 630, , 631, , 632, , 633, , 634, , 635, , 636, , 637, , 638, , 639, , 640, , 641, , 642, , 643, , 644, , 645, , 646, , 647, , 648, , 649, , 650, , 651, , 652, , 653, , 654, , 655, , 656, , 657, , 658, , 659, , 660, , 661, , 662, , 663, , 664, , 665, , 666, , 667, , 668, , 669, , 670, , 671, , 672, , 673, , 674, , 675, , 676, , 677, , 678, , 679, , 680, , 681, , 682, , 683, , 684, , 685, , 686, , 687, , 688, , 689, , 690, , 691, , 692, , 693, , 694, , 695, , 696, , 697, , 698, , 699, , 700, , 701, , 702, , 703, , 704, , 705, , 706, , 707, , 708, , 709, , 710, , 711, , 712, , 713, , 714, , 715, , 716, , 717, , 718, , 719, , 720, , 721, , 722, , 723, , 724, , 725, , 726, , 727, , 728, , 729, , 730, , 731, , 732, , 733, , 734, , 735, , 736, , 737, , 738, , 739, , 740, , 741, , 742, , 743, , 744, , 745, , 746, , 747, , 748, , 749, , 750, , 751, , 752, , 753, , 754, , 755, , 756, , 757, , 758, , 759, , 760, , 761, , 762, , 763, , 764, , 765, , 766, , 767, , 768, , 769, , 770, , 771, , 772, , 773, , 774, , 775, , 776, , 777, , 778, , 779, , 780, , 781, , 782, , 783, , 784, , 785, , 786, , 787, , 788, , 789, , 790, , 791, , 792, , 793, , 794, , 795, , 796, , 797, , 798, , 799, , 800, , 801, , 802, , 803, , 804, , 805, , 806, , 807, , 808, , 809, , 810, , 811, , 812, , 813, , 814, , 815, , 816, , 817, , 818, , 819, , 820, , 821, , 822, , 823, , 824, , 825, , 826, , 827, , 828, , 829, , 830, , 831, , 832, , 833, , 834, , 835, , 836, , 837, , 838, , 839, , 840, , 841, , 842, , 843, , 844, , 845, , 846, , 847, , 848, , 849, , 850, , 851, , 852, , 853, , 854, , 855, , 856, , 857, , 858, , 859, , 860, , 861, , 862, , 863, , 864, , 865, , 866, , 867, , 868, , 869, , 870, , 871, , 872, , 873, , 874, , 875, , 876, , 877, , 878, , 879, , 880, , 881, , 882, , 883, , 884, , 885, , 886, , 887, , 888, , 889, , 890, , 891, , 892, , 893, , 894, , 895, , 896, , 897, , 898, , 899, , 900, , 901, , 902, , 903, , 904, , 905, , 906, , 907, , 908, , 909, , 910, , 911, , 912, , 913, , 914, , 915, , 916, , 917, , 918, , 919, , 920, , 921, , 922, , 923, , 924, , 925, , 926, , 927, , 928, , 929, , 930, , 931, , 932, , 933, , 934, , 935, , 936, , 937, , 938, , 939, , 940, , 941, , 942, , 943, , 944, , 945, , 946, , 947, , 948, , 949, , 950, , 951, , 952, , 953, , 954, , 955, , 956, , 957, , 958, , 959, , 960, , 961, , 962, , 963, , 964, , 965, , 966, , 967, , 968, , 969, , 970, , 971, , 972, , 973, , 974, , 975, , 976, , 977, , 978, , 979, , 980, , 981, , 982, , 983, , 984, , 985, , 986, , 987, , 988, , 989, , 990, , 991, , 992, , 993, , 994, , 995, , 996, , 997, , 998, , 999, , 1000, , 1001, , 1002, , 1003, , 1004, , 1005, , 1006, , 1007, , 1008, , 1009, , 1010, , 1011, , 1012, , 1013, , 1014, , 1015, , 1016, , 1017, , 1018, , 1019, , 1020, , 1021, , 1022, , 1023, , 1024, , 1025, , 1026, , 1027, , 1028, , 1029, , 1030, , 1031, , 1032, , 1033, , 1034, , 1035, , 1036, , 1037, , 1038, , 1039, , 1040, , 1041, , 1042, , 1043, , 1044, , 1045, , 1046, , 1047, , 1048, , 1049, , 1050, , 1051, , 1052, , 1053, , 1054, , 1055, , 1056, , 1057, , 1058, , 1059, , 1060, , 1061, , 1062, , 1063, , 1064, , 1065, , 1066, , 1067, , 1068, , 1069, , 1070, , 1071, , 1072, , 1073, , 1074, , 1075, , 1076, , 1077, , 1078, , 1079, , 1080, , 1081, , 1082, , 1083, , 1084, , 1085, , 1086, , 1087, , 1088, , 1089, , 1090, , 1091, , 1092, , 1093, , 1094, , 1095, , 1096, , 1097, , 1098, , 1099, , 1100, , 1101, , 1102, , 1103, , 1104, , 1105, , 1106, , 1107, , 1108, , 1109, , 1110, , 1111, , 1112, , 1113, , 1114, , 1115, , 1116, , 1117, , 1118, , 1119, , 1120, , 1121, , 1122, , 1123, , 1124, , 1125, , 1126, , 1127, , 1128, , 1129, , 1130, , 1131, , 1132, , 1133, , 1134, , 1135, , 1136, , 1137, , 1138, , 1139, , 1140, , 1141, , 1142, , 1143, , 1144, , 1145, , 1146, , 1147, , 1148, , 1149, , 1150, , 1151, , 1152, , 1153, , 1154, , 1155, , 1156, , 1157, , 1158, , 1159, , 1160, , 1161, , 1162, , 1163, , 1164, , 1165, , 1166, , 1167, , 1168, , 1169, , 1170, , 1171, , 1172, , 1173, , 1174, , 1175, , 1176, , 1177, , 1178, , 1179, , 1180, , 1181, , 1182, , 1183, , 1184, , 1185, , 1186, , 1187, , 1188, , 1189, , 1190, , 1191, , 1192, , 1193, , 1194, , 1195, , 1196, , 1197, , 1198, , 1199, , 1200, , 1201, , 1202, 





MotChallenge2DBox
dancetrack0004
Traceback (most recent call last):
  File "/root/autodl-tmp/trackwithdepth/DanceTrack/TrackEval/trackeval/eval.py", line 86, in evaluate
    res[curr_seq] = eval_sequence(curr_seq, dataset, tracker, class_list, metrics_list,
                    ^^^^^^^^^^^^^^^^^^^^^^^^^^^^^^^^^^^^^^^^^^^^^^^^^^^^^^^^^^^^^^^^^^^
  File "/root/autodl-tmp/trackwithdepth/DanceTrack/TrackEval/trackeval/_timing.py", line 17, in wrap
    result = f(*args, **kw)
             ^^^^^^^^^^^^^^
  File "/root/autodl-tmp/trackwithdepth/DanceTrack/TrackEval/trackeval/eval.py", line 191, in eval_sequence
    raw_data = dataset.get_raw_seq_data(tracker, seq)
               ^^^^^^^^^^^^^^^^^^^^^^^^^^^^^^^^^^^^^^
  File "/root/autodl-tmp/trackwithdepth/DanceTrack/TrackEval/trackeval/_timing.py", line 17, in wrap
    result = f(*args, **kw)
             ^^^^^^^^^^^^^^
  File "/root/autodl-tmp/trackwithdepth/DanceTrack/TrackEval/trackeval/datasets/_base_dataset.py", line 93, in get_raw_seq_data
    raw_tracker_data = self._load_raw_file(tracker, seq, is_gt=False)
                       ^^^^^^^^^^^^^^^^^^^^^^^^^^^^^^^^^^^^^^^^^^^^^^
  File "/root/autodl-tmp/trackwithdepth/DanceTrack/TrackEval/trackeval/datasets/mot_challenge_2d_box.py", line 219, in _load_raw_file
    raise TrackEvalException(
DanceTrack.TrackEval.trackeval.utils.TrackEvalException: Tracking data contains the following invalid timesteps in seq dancetrack0018: 504, , 505, , 506, , 507, , 508, , 509, , 510, , 511, , 512, , 513, , 514, , 515, , 516, , 517, , 518, , 519, , 520, , 521, , 522, , 523, , 524, , 525, , 526, , 527, , 528, , 529, , 530, , 531, , 532, , 533, , 534, , 535, , 536, , 537, , 538, , 539, , 540, , 541, , 542, , 543, , 544, , 545, , 546, , 547, , 548, , 549, , 550, , 551, , 552, , 553, , 554, , 555, , 556, , 557, , 558, , 559, , 560, , 561, , 562, , 563, , 564, , 565, , 566, , 567, , 568, , 569, , 570, , 571, , 572, , 573, , 574, , 575, , 576, , 577, , 578, , 579, , 580, , 581, , 582, , 583, , 584, , 585, , 586, , 587, , 588, , 589, , 590, , 591, , 592, , 593, , 594, , 595, , 596, , 597, , 598, , 599, , 600, , 601, , 602, , 603, , 604, , 605, , 606, , 607, , 608, , 609, , 610, , 611, , 612, , 613, , 614, , 615, , 616, , 617, , 618, , 619, , 620, , 621, , 622, , 623, , 624, , 625, , 626, , 627, , 628, , 629, , 630, , 631, , 632, , 633, , 634, , 635, , 636, , 637, , 638, , 639, , 640, , 641, , 642, , 643, , 644, , 645, , 646, , 647, , 648, , 649, , 650, , 651, , 652, , 653, , 654, , 655, , 656, , 657, , 658, , 659, , 660, , 661, , 662, , 663, , 664, , 665, , 666, , 667, , 668, , 669, , 670, , 671, , 672, , 673, , 674, , 675, , 676, , 677, , 678, , 679, , 680, , 681, , 682, , 683, , 684, , 685, , 686, , 687, , 688, , 689, , 690, , 691, , 692, , 693, , 694, , 695, , 696, , 697, , 698, , 699, , 700, , 701, , 702, , 703, , 704, , 705, , 706, , 707, , 708, , 709, , 710, , 711, , 712, , 713, , 714, , 715, , 716, , 717, , 718, , 719, , 720, , 721, , 722, , 723, , 724, , 725, , 726, , 727, , 728, , 729, , 730, , 731, , 732, , 733, , 734, , 735, , 736, , 737, , 738, , 739, , 740, , 741, , 742, , 743, , 744, , 745, , 746, , 747, , 748, , 749, , 750, , 751, , 752, , 753, , 754, , 755, , 756, , 757, , 758, , 759, , 760, , 761, , 762, , 763, , 764, , 765, , 766, , 767, , 768, , 769, , 770, , 771, , 772, , 773, , 774, , 775, , 776, , 777, , 778, , 779, , 780, , 781, , 782, , 783, , 784, , 785, , 786, , 787, , 788, , 789, , 790, , 791, , 792, , 793, , 794, , 795, , 796, , 797, , 798, , 799, , 800, , 801, , 802, , 803, , 804, , 805, , 806, , 807, , 808, , 809, , 810, , 811, , 812, , 813, , 814, , 815, , 816, , 817, , 818, , 819, , 820, , 821, , 822, , 823, , 824, , 825, , 826, , 827, , 828, , 829, , 830, , 831, , 832, , 833, , 834, , 835, , 836, , 837, , 838, , 839, , 840, , 841, , 842, , 843, , 844, , 845, , 846, , 847, , 848, , 849, , 850, , 851, , 852, , 853, , 854, , 855, , 856, , 857, , 858, , 859, , 860, , 861, , 862, , 863, , 864, , 865, , 866, , 867, , 868, , 869, , 870, , 871, , 872, , 873, , 874, , 875, , 876, , 877, , 878, , 879, , 880, , 881, , 882, , 883, , 884, , 885, , 886, , 887, , 888, , 889, , 890, , 891, , 892, , 893, , 894, , 895, , 896, , 897, , 898, , 899, , 900, , 901, , 902, , 903, , 904, , 905, , 906, , 907, , 908, , 909, , 910, , 911, , 912, , 913, , 914, , 915, , 916, , 917, , 918, , 919, , 920, , 921, , 922, , 923, , 924, , 925, , 926, , 927, , 928, , 929, , 930, , 931, , 932, , 933, , 934, , 935, , 936, , 937, , 938, , 939, , 940, , 941, , 942, , 943, , 944, , 945, , 946, , 947, , 948, , 949, , 950, , 951, , 952, , 953, , 954, , 955, , 956, , 957, , 958, , 959, , 960, , 961, , 962, , 963, , 964, , 965, , 966, , 967, , 968, , 969, , 970, , 971, , 972, , 973, , 974, , 975, , 976, , 977, , 978, , 979, , 980, , 981, , 982, , 983, , 984, , 985, , 986, , 987, , 988, , 989, , 990, , 991, , 992, , 993, , 994, , 995, , 996, , 997, , 998, , 999, , 1000, , 1001, , 1002, , 1003, , 1004, , 1005, , 1006, , 1007, , 1008, , 1009, , 1010, , 1011, , 1012, , 1013, , 1014, , 1015, , 1016, , 1017, , 1018, , 1019, , 1020, , 1021, , 1022, , 1023, , 1024, , 1025, , 1026, , 1027, , 1028, , 1029, , 1030, , 1031, , 1032, , 1033, , 1034, , 1035, , 1036, , 1037, , 1038, , 1039, , 1040, , 1041, , 1042, , 1043, , 1044, , 1045, , 1046, , 1047, , 1048, , 1049, , 1050, , 1051, , 1052, , 1053, , 1054, , 1055, , 1056, , 1057, , 1058, , 1059, , 1060, , 1061, , 1062, , 1063, , 1064, , 1065, , 1066, , 1067, , 1068, , 1069, , 1070, , 1071, , 1072, , 1073, , 1074, , 1075, , 1076, , 1077, , 1078, , 1079, , 1080, , 1081, , 1082, , 1083, , 1084, , 1085, , 1086, , 1087, , 1088, , 1089, , 1090, , 1091, , 1092, , 1093, , 1094, , 1095, , 1096, , 1097, , 1098, , 1099, , 1100, , 1101, , 1102, , 1103, , 1104, , 1105, , 1106, , 1107, , 1108, , 1109, , 1110, , 1111, , 1112, , 1113, , 1114, , 1115, , 1116, , 1117, , 1118, , 1119, , 1120, , 1121, , 1122, , 1123, , 1124, , 1125, , 1126, , 1127, , 1128, , 1129, , 1130, , 1131, , 1132, , 1133, , 1134, , 1135, , 1136, , 1137, , 1138, , 1139, , 1140, , 1141, , 1142, , 1143, , 1144, , 1145, , 1146, , 1147, , 1148, , 1149, , 1150, , 1151, , 1152, , 1153, , 1154, , 1155, , 1156, , 1157, , 1158, , 1159, , 1160, , 1161, , 1162, , 1163, , 1164, , 1165, , 1166, , 1167, , 1168, , 1169, , 1170, , 1171, , 1172, , 1173, , 1174, , 1175, , 1176, , 1177, , 1178, , 1179, , 1180, , 1181, , 1182, , 1183, , 1184, , 1185, , 1186, , 1187, , 1188, , 1189, , 1190, , 1191, , 1192, , 1193, , 1194, , 1195, , 1196, , 1197, , 1198, , 1199, , 1200, , 1201, , 1202, 





MotChallenge2DBox
data
Traceback (most recent call last):
  File "/root/autodl-tmp/trackwithdepth/DanceTrack/TrackEval/trackeval/datasets/_base_dataset.py", line 152, in _load_simple_text_file
    fp = open(file)
         ^^^^^^^^^^
FileNotFoundError: [Errno 2] No such file or directory: './trackers/DepthMOT/data/track_results.txt'

During handling of the above exception, another exception occurred:

Traceback (most recent call last):
  File "/root/autodl-tmp/trackwithdepth/DanceTrack/TrackEval/trackeval/eval.py", line 86, in evaluate
    res[curr_seq] = eval_sequence(curr_seq, dataset, tracker, class_list, metrics_list,
                    ^^^^^^^^^^^^^^^^^^^^^^^^^^^^^^^^^^^^^^^^^^^^^^^^^^^^^^^^^^^^^^^^^^^
  File "/root/autodl-tmp/trackwithdepth/DanceTrack/TrackEval/trackeval/_timing.py", line 17, in wrap
    result = f(*args, **kw)
             ^^^^^^^^^^^^^^
  File "/root/autodl-tmp/trackwithdepth/DanceTrack/TrackEval/trackeval/eval.py", line 191, in eval_sequence
    raw_data = dataset.get_raw_seq_data(tracker, seq)
               ^^^^^^^^^^^^^^^^^^^^^^^^^^^^^^^^^^^^^^
  File "/root/autodl-tmp/trackwithdepth/DanceTrack/TrackEval/trackeval/_timing.py", line 17, in wrap
    result = f(*args, **kw)
             ^^^^^^^^^^^^^^
  File "/root/autodl-tmp/trackwithdepth/DanceTrack/TrackEval/trackeval/datasets/_base_dataset.py", line 93, in get_raw_seq_data
    raw_tracker_data = self._load_raw_file(tracker, seq, is_gt=False)
                       ^^^^^^^^^^^^^^^^^^^^^^^^^^^^^^^^^^^^^^^^^^^^^^
  File "/root/autodl-tmp/trackwithdepth/DanceTrack/TrackEval/trackeval/datasets/mot_challenge_2d_box.py", line 200, in _load_raw_file
    read_data, ignore_data = self._load_simple_text_file(file, is_zipped=self.data_is_zipped, zip_file=zip_file)
                             ^^^^^^^^^^^^^^^^^^^^^^^^^^^^^^^^^^^^^^^^^^^^^^^^^^^^^^^^^^^^^^^^^^^^^^^^^^^^^^^^^^^
  File "/root/autodl-tmp/trackwithdepth/DanceTrack/TrackEval/trackeval/datasets/_base_dataset.py", line 209, in _load_simple_text_file
    raise TrackEvalException(
DanceTrack.TrackEval.trackeval.utils.TrackEvalException: File track_results.txt cannot be read because it is either not present or invalidly formatted





MotChallenge2DBox
DepthMOT
Traceback (most recent call last):
  File "/root/autodl-tmp/trackwithdepth/DanceTrack/TrackEval/trackeval/datasets/_base_dataset.py", line 152, in _load_simple_text_file
    fp = open(file)
         ^^^^^^^^^^
FileNotFoundError: [Errno 2] No such file or directory: './YOLOX_outputs/DepthMOT/dancetrack0004.txt'

During handling of the above exception, another exception occurred:

Traceback (most recent call last):
  File "/root/autodl-tmp/trackwithdepth/DanceTrack/TrackEval/trackeval/eval.py", line 86, in evaluate
    res[curr_seq] = eval_sequence(curr_seq, dataset, tracker, class_list, metrics_list,
                    ^^^^^^^^^^^^^^^^^^^^^^^^^^^^^^^^^^^^^^^^^^^^^^^^^^^^^^^^^^^^^^^^^^^
  File "/root/autodl-tmp/trackwithdepth/DanceTrack/TrackEval/trackeval/_timing.py", line 17, in wrap
    result = f(*args, **kw)
             ^^^^^^^^^^^^^^
  File "/root/autodl-tmp/trackwithdepth/DanceTrack/TrackEval/trackeval/eval.py", line 191, in eval_sequence
    raw_data = dataset.get_raw_seq_data(tracker, seq)
               ^^^^^^^^^^^^^^^^^^^^^^^^^^^^^^^^^^^^^^
  File "/root/autodl-tmp/trackwithdepth/DanceTrack/TrackEval/trackeval/_timing.py", line 17, in wrap
    result = f(*args, **kw)
             ^^^^^^^^^^^^^^
  File "/root/autodl-tmp/trackwithdepth/DanceTrack/TrackEval/trackeval/datasets/_base_dataset.py", line 93, in get_raw_seq_data
    raw_tracker_data = self._load_raw_file(tracker, seq, is_gt=False)
                       ^^^^^^^^^^^^^^^^^^^^^^^^^^^^^^^^^^^^^^^^^^^^^^
  File "/root/autodl-tmp/trackwithdepth/DanceTrack/TrackEval/trackeval/datasets/mot_challenge_2d_box.py", line 200, in _load_raw_file
    read_data, ignore_data = self._load_simple_text_file(file, is_zipped=self.data_is_zipped, zip_file=zip_file)
                             ^^^^^^^^^^^^^^^^^^^^^^^^^^^^^^^^^^^^^^^^^^^^^^^^^^^^^^^^^^^^^^^^^^^^^^^^^^^^^^^^^^^
  File "/root/autodl-tmp/trackwithdepth/DanceTrack/TrackEval/trackeval/datasets/_base_dataset.py", line 209, in _load_simple_text_file
    raise TrackEvalException(
DanceTrack.TrackEval.trackeval.utils.TrackEvalException: File dancetrack0004.txt cannot be read because it is either not present or invalidly formatted





